Workbook

Sheet Исходные данные
A1: Дата | B1: Время | C1: № интервала | D1: Значение | H1: Дата | I1: Время | J1: № интервала | K1: Значение | O1: Дата | P1: Время | Q1: № интервала | R1: Значение
A2: 43047 | B2: 0.020833333 | C2: 1 | D2: =[1]Лист1!$D2+[2]Лист1!$D2 -> 0 | H2: 43101 | I2: 0.020833333 | J2: 1 | K2: =[1]Лист1!$J2+[2]Лист1!$J2 -> 24.04 | O2: 43466 | P2: 0.020833333 | Q2: 1 | R2: =[1]Лист1!$P2+[2]Лист1!$P2 -> 25.96
A3: 43047 | B3: 0.041666667 | C3: 2 | D3: =[1]Лист1!$D3+[2]Лист1!$D3 -> 0 | H3: 43101 | I3: 0.041666667 | J3: 2 | K3: =[1]Лист1!$J3+[2]Лист1!$J3 -> 23.72 | O3: 43466 | P3: 0.041666667 | Q3: 2 | R3: =[1]Лист1!$P3+[2]Лист1!$P3 -> 26.8
A4: 43047 | B4: 0.0625 | C4: 3 | D4: =[1]Лист1!$D4+[2]Лист1!$D4 -> 0 | H4: 43101 | I4: 0.0625 | J4: 3 | K4: =[1]Лист1!$J4+[2]Лист1!$J4 -> 22.36 | O4: 43466 | P4: 0.0625 | Q4: 3 | R4: =[1]Лист1!$P4+[2]Лист1!$P4 -> 25.52
A5: 43047 | B5: 0.083333333 | C5: 4 | D5: =[1]Лист1!$D5+[2]Лист1!$D5 -> 0 | H5: 43101 | I5: 0.083333333 | J5: 4 | K5: =[1]Лист1!$J5+[2]Лист1!$J5 -> 22.64 | O5: 43466 | P5: 0.083333333 | Q5: 4 | R5: =[1]Лист1!$P5+[2]Лист1!$P5 -> 22.92
A6: 43047 | B6: 0.10416667 | C6: 5 | D6: =[1]Лист1!$D6+[2]Лист1!$D6 -> 0 | H6: 43101 | I6: 0.10416667 | J6: 5 | K6: =[1]Лист1!$J6+[2]Лист1!$J6 -> 22.12 | O6: 43466 | P6: 0.10416667 | Q6: 5 | R6: =[1]Лист1!$P6+[2]Лист1!$P6 -> 22.8
A7: 43047 | B7: 0.125 | C7: 6 | D7: =[1]Лист1!$D7+[2]Лист1!$D7 -> 0 | H7: 43101 | I7: 0.125 | J7: 6 | K7: =[1]Лист1!$J7+[2]Лист1!$J7 -> 19.64 | O7: 43466 | P7: 0.125 | Q7: 6 | R7: =[1]Лист1!$P7+[2]Лист1!$P7 -> 20.4
A8: 43047 | B8: 0.14583333 | C8: 7 | D8: =[1]Лист1!$D8+[2]Лист1!$D8 -> 0 | H8: 43101 | I8: 0.14583333 | J8: 7 | K8: =[1]Лист1!$J8+[2]Лист1!$J8 -> 16.68 | O8: 43466 | P8: 0.14583333 | Q8: 7 | R8: =[1]Лист1!$P8+[2]Лист1!$P8 -> 17.36
A9: 43047 | B9: 0.16666667 | C9: 8 | D9: =[1]Лист1!$D9+[2]Лист1!$D9 -> 0 | H9: 43101 | I9: 0.16666667 | J9: 8 | K9: =[1]Лист1!$J9+[2]Лист1!$J9 -> 15.92 | O9: 43466 | P9: 0.16666667 | Q9: 8 | R9: =[1]Лист1!$P9+[2]Лист1!$P9 -> 17.04
A10: 43047 | B10: 0.1875 | C10: 9 | D10: =[1]Лист1!$D10+[2]Лист1!$D10 -> 0 | H10: 43101 | I10: 0.1875 | J10: 9 | K10: =[1]Лист1!$J10+[2]Лист1!$J10 -> 15.64 | O10: 43466 | P10: 0.1875 | Q10: 9 | R10: =[1]Лист1!$P10+[2]Лист1!$P10 -> 15.88
A11: 43047 | B11: 0.20833333 | C11: 10 | D11: =[1]Лист1!$D11+[2]Лист1!$D11 -> 0 | H11: 43101 | I11: 0.20833333 | J11: 10 | K11: =[1]Лист1!$J11+[2]Лист1!$J11 -> 16 | O11: 43466 | P11: 0.20833333 | Q11: 10 | R11: =[1]Лист1!$P11+[2]Лист1!$P11 -> 16.52
A12: 43047 | B12: 0.22916667 | C12: 11 | D12: =[1]Лист1!$D12+[2]Лист1!$D12 -> 0 | H12: 43101 | I12: 0.22916667 | J12: 11 | K12: =[1]Лист1!$J12+[2]Лист1!$J12 -> 15.88 | O12: 43466 | P12: 0.22916667 | Q12: 11 | R12: =[1]Лист1!$P12+[2]Лист1!$P12 -> 14.72
A13: 43047 | B13: 0.25 | C13: 12 | D13: =[1]Лист1!$D13+[2]Лист1!$D13 -> 0 | H13: 43101 | I13: 0.25 | J13: 12 | K13: =[1]Лист1!$J13+[2]Лист1!$J13 -> 15.16 | O13: 43466 | P13: 0.25 | Q13: 12 | R13: =[1]Лист1!$P13+[2]Лист1!$P13 -> 14.72
... A48: 43047 | B48: 0.97916667 | C48: 47 | D48: =[1]Лист1!$D48+[2]Лист1!$D48 -> 0 | H48: 43101 | I48: 0.97916667 | J48: 47 | K48: =[1]Лист1!$J48+[2]Лист1!$J48 -> 26.84 | O48: 43466 | P48: 0.97916667 | Q48: 47 | R48: =[1]Лист1!$P48+[2]Лист1!$P48 -> 26.52
A49: 43047 | B49: 24:00 | C49: 48 | D49: =[1]Лист1!$D49+[2]Лист1!$D49 -> 0 | H49: 43101 | I49: 24:00 | J49: 48 | K49: =[1]Лист1!$J49+[2]Лист1!$J49 -> 25.2 | O49: 43466 | P49: 24:00 | Q49: 48 | R49: =[1]Лист1!$P49+[2]Лист1!$P49 -> 25.04
A50: 43048 | B50: 0.020833333 | C50: 1 | D50: =[1]Лист1!$D50+[2]Лист1!$D50 -> 0 | H50: 43102 | I50: 0.020833333 | J50: 1 | K50: =[1]Лист1!$J50+[2]Лист1!$J50 -> 21.72 | O50: 43467 | P50: 0.020833333 | Q50: 1 | R50: =[1]Лист1!$P50+[2]Лист1!$P50 -> 22.2
A51: 43048 | B51: 0.041666667 | C51: 2 | D51: =[1]Лист1!$D51+[2]Лист1!$D51 -> 0 | H51: 43102 | I51: 0.041666667 | J51: 2 | K51: =[1]Лист1!$J51+[2]Лист1!$J51 -> 21.08 | O51: 43467 | P51: 0.041666667 | Q51: 2 | R51: =[1]Лист1!$P51+[2]Лист1!$P51 -> 21.12
A52: 43048 | B52: 0.0625 | C52: 3 | D52: =[1]Лист1!$D52+[2]Лист1!$D52 -> 0 | H52: 43102 | I52: 0.0625 | J52: 3 | K52: =[1]Лист1!$J52+[2]Лист1!$J52 -> 21.72 | O52: 43467 | P52: 0.0625 | Q52: 3 | R52: =[1]Лист1!$P52+[2]Лист1!$P52 -> 18.36
A53: 43048 | B53: 0.083333333 | C53: 4 | D53: =[1]Лист1!$D53+[2]Лист1!$D53 -> 0 | H53: 43102 | I53: 0.083333333 | J53: 4 | K53: =[1]Лист1!$J53+[2]Лист1!$J53 -> 18.8 | O53: 43467 | P53: 0.083333333 | Q53: 4 | R53: =[1]Лист1!$P53+[2]Лист1!$P53 -> 16.76
A54: 43048 | B54: 0.10416667 | C54: 5 | D54: =[1]Лист1!$D54+[2]Лист1!$D54 -> 0 | H54: 43102 | I54: 0.10416667 | J54: 5 | K54: =[1]Лист1!$J54+[2]Лист1!$J54 -> 16.4 | O54: 43467 | P54: 0.10416667 | Q54: 5 | R54: =[1]Лист1!$P54+[2]Лист1!$P54 -> 16.28
A55: 43048 | B55: 0.125 | C55: 6 | D55: =[1]Лист1!$D55+[2]Лист1!$D55 -> 0 | H55: 43102 | I55: 0.125 | J55: 6 | K55: =[1]Лист1!$J55+[2]Лист1!$J55 -> 16.2 | O55: 43467 | P55: 0.125 | Q55: 6 | R55: =[1]Лист1!$P55+[2]Лист1!$P55 -> 15.16
A56: 43048 | B56: 0.14583333 | C56: 7 | D56: =[1]Лист1!$D56+[2]Лист1!$D56 -> 0 | H56: 43102 | I56: 0.14583333 | J56: 7 | K56: =[1]Лист1!$J56+[2]Лист1!$J56 -> 14.64 | O56: 43467 | P56: 0.14583333 | Q56: 7 | R56: =[1]Лист1!$P56+[2]Лист1!$P56 -> 14.48
A57: 43048 | B57: 0.16666667 | C57: 8 | D57: =[1]Лист1!$D57+[2]Лист1!$D57 -> 0 | H57: 43102 | I57: 0.16666667 | J57: 8 | K57: =[1]Лист1!$J57+[2]Лист1!$J57 -> 15.32 | O57: 43467 | P57: 0.16666667 | Q57: 8 | R57: =[1]Лист1!$P57+[2]Лист1!$P57 -> 13.44
A58: 43048 | B58: 0.1875 | C58: 9 | D58: =[1]Лист1!$D58+[2]Лист1!$D58 -> 0 | H58: 43102 | I58: 0.1875 | J58: 9 | K58: =[1]Лист1!$J58+[2]Лист1!$J58 -> 15.28 | O58: 43467 | P58: 0.1875 | Q58: 9 | R58: =[1]Лист1!$P58+[2]Лист1!$P58 -> 14.32
A59: 43048 | B59: 0.20833333 | C59: 10 | D59: =[1]Лист1!$D59+[2]Лист1!$D59 -> 0 | H59: 43102 | I59: 0.20833333 | J59: 10 | K59: =[1]Лист1!$J59+[2]Лист1!$J59 -> 15.04 | O59: 43467 | P59: 0.20833333 | Q59: 10 | R59: =[1]Лист1!$P59+[2]Лист1!$P59 -> 14.68
A60: 43048 | B60: 0.22916667 | C60: 11 | D60: =[1]Лист1!$D60+[2]Лист1!$D60 -> 0 | H60: 43102 | I60: 0.22916667 | J60: 11 | K60: =[1]Лист1!$J60+[2]Лист1!$J60 -> 14.16 | O60: 43467 | P60: 0.22916667 | Q60: 11 | R60: =[1]Лист1!$P60+[2]Лист1!$P60 -> 13.84
A61: 43048 | B61: 0.25 | C61: 12 | D61: =[1]Лист1!$D61+[2]Лист1!$D61 -> 0 | H61: 43102 | I61: 0.25 | J61: 12 | K61: =[1]Лист1!$J61+[2]Лист1!$J61 -> 14.68 | O61: 43467 | P61: 0.25 | Q61: 12 | R61: =[1]Лист1!$P61+[2]Лист1!$P61 -> 14.84
... A96: 43048 | B96: 0.97916667 | C96: 47 | D96: =[1]Лист1!$D96+[2]Лист1!$D96 -> 0 | H96: 43102 | I96: 0.97916667 | J96: 47 | K96: =[1]Лист1!$J96+[2]Лист1!$J96 -> 28.44 | O96: 43467 | P96: 0.97916667 | Q96: 47 | R96: =[1]Лист1!$P96+[2]Лист1!$P96 -> 28.64
A97: 43048 | B97: 24:00 | C97: 48 | D97: =[1]Лист1!$D97+[2]Лист1!$D97 -> 0 | H97: 43102 | I97: 24:00 | J97: 48 | K97: =[1]Лист1!$J97+[2]Лист1!$J97 -> 23.68 | O97: 43467 | P97: 24:00 | Q97: 48 | R97: =[1]Лист1!$P97+[2]Лист1!$P97 -> 26.4
A98: 43049 | B98: 0.020833333 | C98: 1 | D98: =[1]Лист1!$D98+[2]Лист1!$D98 -> 0 | H98: 43103 | I98: 0.020833333 | J98: 1 | K98: =[1]Лист1!$J98+[2]Лист1!$J98 -> 22.52 | O98: 43468 | P98: 0.020833333 | Q98: 1 | R98: =[1]Лист1!$P98+[2]Лист1!$P98 -> 22.96
A99: 43049 | B99: 0.041666667 | C99: 2 | D99: =[1]Лист1!$D99+[2]Лист1!$D99 -> 0 | H99: 43103 | I99: 0.041666667 | J99: 2 | K99: =[1]Лист1!$J99+[2]Лист1!$J99 -> 19.28 | O99: 43468 | P99: 0.041666667 | Q99: 2 | R99: =[1]Лист1!$P99+[2]Лист1!$P99 -> 22.48
A100: 43049 | B100: 0.0625 | C100: 3 | D100: =[1]Лист1!$D100+[2]Лист1!$D100 -> 0 | H100: 43103 | I100: 0.0625 | J100: 3 | K100: =[1]Лист1!$J100+[2]Лист1!$J100 -> 17.56 | O100: 43468 | P100: 0.0625 | Q100: 3 | R100: =[1]Лист1!$P100+[2]Лист1!$P100 -> 18.88
A101: 43049 | B101: 0.083333333 | C101: 4 | D101: =[1]Лист1!$D101+[2]Лист1!$D101 -> 0 | H101: 43103 | I101: 0.083333333 | J101: 4 | K101: =[1]Лист1!$J101+[2]Лист1!$J101 -> 16.6 | O101: 43468 | P101: 0.083333333 | Q101: 4 | R101: =[1]Лист1!$P101+[2]Лист1!$P101 -> 16.4
A102: 43049 | B102: 0.10416667 | C102: 5 | D102: =[1]Лист1!$D102+[2]Лист1!$D102 -> 0 | H102: 43103 | I102: 0.10416667 | J102: 5 | K102: =[1]Лист1!$J102+[2]Лист1!$J102 -> 15.96 | O102: 43468 | P102: 0.10416667 | Q102: 5 | R102: =[1]Лист1!$P102+[2]Лист1!$P102 -> 17.2
A103: 43049 | B103: 0.125 | C103: 6 | D103: =[1]Лист1!$D103+[2]Лист1!$D103 -> 0 | H103: 43103 | I103: 0.125 | J103: 6 | K103: =[1]Лист1!$J103+[2]Лист1!$J103 -> 14.76 | O103: 43468 | P103: 0.125 | Q103: 6 | R103: =[1]Лист1!$P103+[2]Лист1!$P103 -> 16.84
A104: 43049 | B104: 0.14583333 | C104: 7 | D104: =[1]Лист1!$D104+[2]Лист1!$D104 -> 0 | H104: 43103 | I104: 0.14583333 | J104: 7 | K104: =[1]Лист1!$J104+[2]Лист1!$J104 -> 14.04 | O104: 43468 | P104: 0.14583333 | Q104: 7 | R104: =[1]Лист1!$P104+[2]Лист1!$P104 -> 14.68
A105: 43049 | B105: 0.16666667 | C105: 8 | D105: =[1]Лист1!$D105+[2]Лист1!$D105 -> 0 | H105: 43103 | I105: 0.16666667 | J105: 8 | K105: =[1]Лист1!$J105+[2]Лист1!$J105 -> 13.92 | O105: 43468 | P105: 0.16666667 | Q105: 8 | R105: =[1]Лист1!$P105+[2]Лист1!$P105 -> 15.2
A106: 43049 | B106: 0.1875 | C106: 9 | D106: =[1]Лист1!$D106+[2]Лист1!$D106 -> 0 | H106: 43103 | I106: 0.1875 | J106: 9 | K106: =[1]Лист1!$J106+[2]Лист1!$J106 -> 12.88 | O106: 43468 | P106: 0.1875 | Q106: 9 | R106: =[1]Лист1!$P106+[2]Лист1!$P106 -> 14.48
A107: 43049 | B107: 0.20833333 | C107: 10 | D107: =[1]Лист1!$D107+[2]Лист1!$D107 -> 0 | H107: 43103 | I107: 0.20833333 | J107: 10 | K107: =[1]Лист1!$J107+[2]Лист1!$J107 -> 12.76 | O107: 43468 | P107: 0.20833333 | Q107: 10 | R107: =[1]Лист1!$P107+[2]Лист1!$P107 -> 13.8
A108: 43049 | B108: 0.22916667 | C108: 11 | D108: =[1]Лист1!$D108+[2]Лист1!$D108 -> 0 | H108: 43103 | I108: 0.22916667 | J108: 11 | K108: =[1]Лист1!$J108+[2]Лист1!$J108 -> 13.72 | O108: 43468 | P108: 0.22916667 | Q108: 11 | R108: =[1]Лист1!$P108+[2]Лист1!$P108 -> 14.6
...
