Workbook

Sheet Исходные данные
A1: Дата | B1: Время | C1: № интервала | D1: Значение | H1: Дата | I1: Время | J1: № интервала | K1: Значение | O1: Дата | P1: Время | Q1: № интервала | R1: Значение
A2: 42736 | B2: 0.020833333 | C2: 1 | D2: =[1]Лист1!$D2+[2]Лист1!$D2+[3]Лист1!$D2+[4]Лист1!$D2+[5]Лист1!$D2+[6]Лист1!$D2 -> 94.35 | H2: 43101 | I2: 0.020833333 | J2: 1 | K2: =[1]Лист1!$J2+[2]Лист1!$J2+[3]Лист1!$J2+[4]Лист1!$J2+[5]Лист1!$J2+[6]Лист1!$J2 -> 98.24 | O2: 43466 | P2: 0.020833333 | Q2: 1 | R2: =[1]Лист1!$P2+[2]Лист1!$P2+[3]Лист1!$P2+[4]Лист1!$P2+[5]Лист1!$P2+[6]Лист1!$P2 -> 90.39
A3: 42736 | B3: 0.041666667 | C3: 2 | D3: =[1]Лист1!$D3+[2]Лист1!$D3+[3]Лист1!$D3+[4]Лист1!$D3+[5]Лист1!$D3+[6]Лист1!$D3 -> 88.63 | H3: 43101 | I3: 0.041666667 | J3: 2 | K3: =[1]Лист1!$J3+[2]Лист1!$J3+[3]Лист1!$J3+[4]Лист1!$J3+[5]Лист1!$J3+[6]Лист1!$J3 -> 92.36 | O3: 43466 | P3: 0.041666667 | Q3: 2 | R3: =[1]Лист1!$P3+[2]Лист1!$P3+[3]Лист1!$P3+[4]Лист1!$P3+[5]Лист1!$P3+[6]Лист1!$P3 -> 86.52
A4: 42736 | B4: 0.0625 | C4: 3 | D4: =[1]Лист1!$D4+[2]Лист1!$D4+[3]Лист1!$D4+[4]Лист1!$D4+[5]Лист1!$D4+[6]Лист1!$D4 -> 83.33 | H4: 43101 | I4: 0.0625 | J4: 3 | K4: =[1]Лист1!$J4+[2]Лист1!$J4+[3]Лист1!$J4+[4]Лист1!$J4+[5]Лист1!$J4+[6]Лист1!$J4 -> 92.27 | O4: 43466 | P4: 0.0625 | Q4: 3 | R4: =[1]Лист1!$P4+[2]Лист1!$P4+[3]Лист1!$P4+[4]Лист1!$P4+[5]Лист1!$P4+[6]Лист1!$P4 -> 84.02
A5: 42736 | B5: 0.083333333 | C5: 4 | D5: =[1]Лист1!$D5+[2]Лист1!$D5+[3]Лист1!$D5+[4]Лист1!$D5+[5]Лист1!$D5+[6]Лист1!$D5 -> 80.59 | H5: 43101 | I5: 0.083333333 | J5: 4 | K5: =[1]Лист1!$J5+[2]Лист1!$J5+[3]Лист1!$J5+[4]Лист1!$J5+[5]Лист1!$J5+[6]Лист1!$J5 -> 83.44 | O5: 43466 | P5: 0.083333333 | Q5: 4 | R5: =[1]Лист1!$P5+[2]Лист1!$P5+[3]Лист1!$P5+[4]Лист1!$P5+[5]Лист1!$P5+[6]Лист1!$P5 -> 80.83
A6: 42736 | B6: 0.10416667 | C6: 5 | D6: =[1]Лист1!$D6+[2]Лист1!$D6+[3]Лист1!$D6+[4]Лист1!$D6+[5]Лист1!$D6+[6]Лист1!$D6 -> 71.4 | H6: 43101 | I6: 0.10416667 | J6: 5 | K6: =[1]Лист1!$J6+[2]Лист1!$J6+[3]Лист1!$J6+[4]Лист1!$J6+[5]Лист1!$J6+[6]Лист1!$J6 -> 74.45 | O6: 43466 | P6: 0.10416667 | Q6: 5 | R6: =[1]Лист1!$P6+[2]Лист1!$P6+[3]Лист1!$P6+[4]Лист1!$P6+[5]Лист1!$P6+[6]Лист1!$P6 -> 75.76
A7: 42736 | B7: 0.125 | C7: 6 | D7: =[1]Лист1!$D7+[2]Лист1!$D7+[3]Лист1!$D7+[4]Лист1!$D7+[5]Лист1!$D7+[6]Лист1!$D7 -> 67.87 | H7: 43101 | I7: 0.125 | J7: 6 | K7: =[1]Лист1!$J7+[2]Лист1!$J7+[3]Лист1!$J7+[4]Лист1!$J7+[5]Лист1!$J7+[6]Лист1!$J7 -> 72.37 | O7: 43466 | P7: 0.125 | Q7: 6 | R7: =[1]Лист1!$P7+[2]Лист1!$P7+[3]Лист1!$P7+[4]Лист1!$P7+[5]Лист1!$P7+[6]Лист1!$P7 -> 69.8
A8: 42736 | B8: 0.14583333 | C8: 7 | D8: =[1]Лист1!$D8+[2]Лист1!$D8+[3]Лист1!$D8+[4]Лист1!$D8+[5]Лист1!$D8+[6]Лист1!$D8 -> 61.7 | H8: 43101 | I8: 0.14583333 | J8: 7 | K8: =[1]Лист1!$J8+[2]Лист1!$J8+[3]Лист1!$J8+[4]Лист1!$J8+[5]Лист1!$J8+[6]Лист1!$J8 -> 67.48 | O8: 43466 | P8: 0.14583333 | Q8: 7 | R8: =[1]Лист1!$P8+[2]Лист1!$P8+[3]Лист1!$P8+[4]Лист1!$P8+[5]Лист1!$P8+[6]Лист1!$P8 -> 66.95
A9: 42736 | B9: 0.16666667 | C9: 8 | D9: =[1]Лист1!$D9+[2]Лист1!$D9+[3]Лист1!$D9+[4]Лист1!$D9+[5]Лист1!$D9+[6]Лист1!$D9 -> 59.79 | H9: 43101 | I9: 0.16666667 | J9: 8 | K9: =[1]Лист1!$J9+[2]Лист1!$J9+[3]Лист1!$J9+[4]Лист1!$J9+[5]Лист1!$J9+[6]Лист1!$J9 -> 61.48 | O9: 43466 | P9: 0.16666667 | Q9: 8 | R9: =[1]Лист1!$P9+[2]Лист1!$P9+[3]Лист1!$P9+[4]Лист1!$P9+[5]Лист1!$P9+[6]Лист1!$P9 -> 61.71
A10: 42736 | B10: 0.1875 | C10: 9 | D10: =[1]Лист1!$D10+[2]Лист1!$D10+[3]Лист1!$D10+[4]Лист1!$D10+[5]Лист1!$D10+[6]Лист1!$D10 -> 53.73 | H10: 43101 | I10: 0.1875 | J10: 9 | K10: =[1]Лист1!$J10+[2]Лист1!$J10+[3]Лист1!$J10+[4]Лист1!$J10+[5]Лист1!$J10+[6]Лист1!$J10 -> 58.6 | O10: 43466 | P10: 0.1875 | Q10: 9 | R10: =[1]Лист1!$P10+[2]Лист1!$P10+[3]Лист1!$P10+[4]Лист1!$P10+[5]Лист1!$P10+[6]Лист1!$P10 -> 59.12
A11: 42736 | B11: 0.20833333 | C11: 10 | D11: =[1]Лист1!$D11+[2]Лист1!$D11+[3]Лист1!$D11+[4]Лист1!$D11+[5]Лист1!$D11+[6]Лист1!$D11 -> 51.14 | H11: 43101 | I11: 0.20833333 | J11: 10 | K11: =[1]Лист1!$J11+[2]Лист1!$J11+[3]Лист1!$J11+[4]Лист1!$J11+[5]Лист1!$J11+[6]Лист1!$J11 -> 57.61 | O11: 43466 | P11: 0.20833333 | Q11: 10 | R11: =[1]Лист1!$P11+[2]Лист1!$P11+[3]Лист1!$P11+[4]Лист1!$P11+[5]Лист1!$P11+[6]Лист1!$P11 -> 55.61
A12: 42736 | B12: 0.22916667 | C12: 11 | D12: =[1]Лист1!$D12+[2]Лист1!$D12+[3]Лист1!$D12+[4]Лист1!$D12+[5]Лист1!$D12+[6]Лист1!$D12 -> 49.49 | H12: 43101 | I12: 0.22916667 | J12: 11 | K12: =[1]Лист1!$J12+[2]Лист1!$J12+[3]Лист1!$J12+[4]Лист1!$J12+[5]Лист1!$J12+[6]Лист1!$J12 -> 55.1 | O12: 43466 | P12: 0.22916667 | Q12: 11 | R12: =[1]Лист1!$P12+[2]Лист1!$P12+[3]Лист1!$P12+[4]Лист1!$P12+[5]Лист1!$P12+[6]Лист1!$P12 -> 52.84
A13: 42736 | B13: 0.25 | C13: 12 | D13: =[1]Лист1!$D13+[2]Лист1!$D13+[3]Лист1!$D13+[4]Лист1!$D13+[5]Лист1!$D13+[6]Лист1!$D13 -> 48.71 | H13: 43101 | I13: 0.25 | J13: 12 | K13: =[1]Лист1!$J13+[2]Лист1!$J13+[3]Лист1!$J13+[4]Лист1!$J13+[5]Лист1!$J13+[6]Лист1!$J13 -> 53.36 | O13: 43466 | P13: 0.25 | Q13: 12 | R13: =[1]Лист1!$P13+[2]Лист1!$P13+[3]Лист1!$P13+[4]Лист1!$P13+[5]Лист1!$P13+[6]Лист1!$P13 -> 51.95
... A48: 42736 | B48: 0.97916667 | C48: 47 | D48: =[1]Лист1!$D48+[2]Лист1!$D48+[3]Лист1!$D48+[4]Лист1!$D48+[5]Лист1!$D48+[6]Лист1!$D48 -> 99.56 | H48: 43101 | I48: 0.97916667 | J48: 47 | K48: =[1]Лист1!$J48+[2]Лист1!$J48+[3]Лист1!$J48+[4]Лист1!$J48+[5]Лист1!$J48+[6]Лист1!$J48 -> 98.25 | O48: 43466 | P48: 0.97916667 | Q48: 47 | R48: =[1]Лист1!$P48+[2]Лист1!$P48+[3]Лист1!$P48+[4]Лист1!$P48+[5]Лист1!$P48+[6]Лист1!$P48 -> 91.04
A49: 42736 | B49: 24:00 | C49: 48 | D49: =[1]Лист1!$D49+[2]Лист1!$D49+[3]Лист1!$D49+[4]Лист1!$D49+[5]Лист1!$D49+[6]Лист1!$D49 -> 90.95 | H49: 43101 | I49: 24:00 | J49: 48 | K49: =[1]Лист1!$J49+[2]Лист1!$J49+[3]Лист1!$J49+[4]Лист1!$J49+[5]Лист1!$J49+[6]Лист1!$J49 -> 93.84 | O49: 43466 | P49: 24:00 | Q49: 48 | R49: =[1]Лист1!$P49+[2]Лист1!$P49+[3]Лист1!$P49+[4]Лист1!$P49+[5]Лист1!$P49+[6]Лист1!$P49 -> 83.2
A50: 42737 | B50: 0.020833333 | C50: 1 | D50: =[1]Лист1!$D50+[2]Лист1!$D50+[3]Лист1!$D50+[4]Лист1!$D50+[5]Лист1!$D50+[6]Лист1!$D50 -> 84.54 | H50: 43102 | I50: 0.020833333 | J50: 1 | K50: =[1]Лист1!$J50+[2]Лист1!$J50+[3]Лист1!$J50+[4]Лист1!$J50+[5]Лист1!$J50+[6]Лист1!$J50 -> 86.32 | O50: 43467 | P50: 0.020833333 | Q50: 1 | R50: =[1]Лист1!$P50+[2]Лист1!$P50+[3]Лист1!$P50+[4]Лист1!$P50+[5]Лист1!$P50+[6]Лист1!$P50 -> 77.82
A51: 42737 | B51: 0.041666667 | C51: 2 | D51: =[1]Лист1!$D51+[2]Лист1!$D51+[3]Лист1!$D51+[4]Лист1!$D51+[5]Лист1!$D51+[6]Лист1!$D51 -> 76.55 | H51: 43102 | I51: 0.041666667 | J51: 2 | K51: =[1]Лист1!$J51+[2]Лист1!$J51+[3]Лист1!$J51+[4]Лист1!$J51+[5]Лист1!$J51+[6]Лист1!$J51 -> 77.57 | O51: 43467 | P51: 0.041666667 | Q51: 2 | R51: =[1]Лист1!$P51+[2]Лист1!$P51+[3]Лист1!$P51+[4]Лист1!$P51+[5]Лист1!$P51+[6]Лист1!$P51 -> 69.5
A52: 42737 | B52: 0.0625 | C52: 3 | D52: =[1]Лист1!$D52+[2]Лист1!$D52+[3]Лист1!$D52+[4]Лист1!$D52+[5]Лист1!$D52+[6]Лист1!$D52 -> 69.49 | H52: 43102 | I52: 0.0625 | J52: 3 | K52: =[1]Лист1!$J52+[2]Лист1!$J52+[3]Лист1!$J52+[4]Лист1!$J52+[5]Лист1!$J52+[6]Лист1!$J52 -> 69.29 | O52: 43467 | P52: 0.0625 | Q52: 3 | R52: =[1]Лист1!$P52+[2]Лист1!$P52+[3]Лист1!$P52+[4]Лист1!$P52+[5]Лист1!$P52+[6]Лист1!$P52 -> 66
A53: 42737 | B53: 0.083333333 | C53: 4 | D53: =[1]Лист1!$D53+[2]Лист1!$D53+[3]Лист1!$D53+[4]Лист1!$D53+[5]Лист1!$D53+[6]Лист1!$D53 -> 60.13 | H53: 43102 | I53: 0.083333333 | J53: 4 | K53: =[1]Лист1!$J53+[2]Лист1!$J53+[3]Лист1!$J53+[4]Лист1!$J53+[5]Лист1!$J53+[6]Лист1!$J53 -> 64.85 | O53: 43467 | P53: 0.083333333 | Q53: 4 | R53: =[1]Лист1!$P53+[2]Лист1!$P53+[3]Лист1!$P53+[4]Лист1!$P53+[5]Лист1!$P53+[6]Лист1!$P53 -> 62.73
A54: 42737 | B54: 0.10416667 | C54: 5 | D54: =[1]Лист1!$D54+[2]Лист1!$D54+[3]Лист1!$D54+[4]Лист1!$D54+[5]Лист1!$D54+[6]Лист1!$D54 -> 56.43 | H54: 43102 | I54: 0.10416667 | J54: 5 | K54: =[1]Лист1!$J54+[2]Лист1!$J54+[3]Лист1!$J54+[4]Лист1!$J54+[5]Лист1!$J54+[6]Лист1!$J54 -> 58.07 | O54: 43467 | P54: 0.10416667 | Q54: 5 | R54: =[1]Лист1!$P54+[2]Лист1!$P54+[3]Лист1!$P54+[4]Лист1!$P54+[5]Лист1!$P54+[6]Лист1!$P54 -> 55.89
A55: 42737 | B55: 0.125 | C55: 6 | D55: =[1]Лист1!$D55+[2]Лист1!$D55+[3]Лист1!$D55+[4]Лист1!$D55+[5]Лист1!$D55+[6]Лист1!$D55 -> 50.63 | H55: 43102 | I55: 0.125 | J55: 6 | K55: =[1]Лист1!$J55+[2]Лист1!$J55+[3]Лист1!$J55+[4]Лист1!$J55+[5]Лист1!$J55+[6]Лист1!$J55 -> 53.75 | O55: 43467 | P55: 0.125 | Q55: 6 | R55: =[1]Лист1!$P55+[2]Лист1!$P55+[3]Лист1!$P55+[4]Лист1!$P55+[5]Лист1!$P55+[6]Лист1!$P55 -> 54.23
A56: 42737 | B56: 0.14583333 | C56: 7 | D56: =[1]Лист1!$D56+[2]Лист1!$D56+[3]Лист1!$D56+[4]Лист1!$D56+[5]Лист1!$D56+[6]Лист1!$D56 -> 48.85 | H56: 43102 | I56: 0.14583333 | J56: 7 | K56: =[1]Лист1!$J56+[2]Лист1!$J56+[3]Лист1!$J56+[4]Лист1!$J56+[5]Лист1!$J56+[6]Лист1!$J56 -> 50.57 | O56: 43467 | P56: 0.14583333 | Q56: 7 | R56: =[1]Лист1!$P56+[2]Лист1!$P56+[3]Лист1!$P56+[4]Лист1!$P56+[5]Лист1!$P56+[6]Лист1!$P56 -> 51.63
A57: 42737 | B57: 0.16666667 | C57: 8 | D57: =[1]Лист1!$D57+[2]Лист1!$D57+[3]Лист1!$D57+[4]Лист1!$D57+[5]Лист1!$D57+[6]Лист1!$D57 -> 47.37 | H57: 43102 | I57: 0.16666667 | J57: 8 | K57: =[1]Лист1!$J57+[2]Лист1!$J57+[3]Лист1!$J57+[4]Лист1!$J57+[5]Лист1!$J57+[6]Лист1!$J57 -> 46.95 | O57: 43467 | P57: 0.16666667 | Q57: 8 | R57: =[1]Лист1!$P57+[2]Лист1!$P57+[3]Лист1!$P57+[4]Лист1!$P57+[5]Лист1!$P57+[6]Лист1!$P57 -> 50.8
A58: 42737 | B58: 0.1875 | C58: 9 | D58: =[1]Лист1!$D58+[2]Лист1!$D58+[3]Лист1!$D58+[4]Лист1!$D58+[5]Лист1!$D58+[6]Лист1!$D58 -> 46.05 | H58: 43102 | I58: 0.1875 | J58: 9 | K58: =[1]Лист1!$J58+[2]Лист1!$J58+[3]Лист1!$J58+[4]Лист1!$J58+[5]Лист1!$J58+[6]Лист1!$J58 -> 46.33 | O58: 43467 | P58: 0.1875 | Q58: 9 | R58: =[1]Лист1!$P58+[2]Лист1!$P58+[3]Лист1!$P58+[4]Лист1!$P58+[5]Лист1!$P58+[6]Лист1!$P58 -> 51.37
A59: 42737 | B59: 0.20833333 | C59: 10 | D59: =[1]Лист1!$D59+[2]Лист1!$D59+[3]Лист1!$D59+[4]Лист1!$D59+[5]Лист1!$D59+[6]Лист1!$D59 -> 45.18 | H59: 43102 | I59: 0.20833333 | J59: 10 | K59: =[1]Лист1!$J59+[2]Лист1!$J59+[3]Лист1!$J59+[4]Лист1!$J59+[5]Лист1!$J59+[6]Лист1!$J59 -> 46.83 | O59: 43467 | P59: 0.20833333 | Q59: 10 | R59: =[1]Лист1!$P59+[2]Лист1!$P59+[3]Лист1!$P59+[4]Лист1!$P59+[5]Лист1!$P59+[6]Лист1!$P59 -> 49.8
A60: 42737 | B60: 0.22916667 | C60: 11 | D60: =[1]Лист1!$D60+[2]Лист1!$D60+[3]Лист1!$D60+[4]Лист1!$D60+[5]Лист1!$D60+[6]Лист1!$D60 -> 45.67 | H60: 43102 | I60: 0.22916667 | J60: 11 | K60: =[1]Лист1!$J60+[2]Лист1!$J60+[3]Лист1!$J60+[4]Лист1!$J60+[5]Лист1!$J60+[6]Лист1!$J60 -> 47.76 | O60: 43467 | P60: 0.22916667 | Q60: 11 | R60: =[1]Лист1!$P60+[2]Лист1!$P60+[3]Лист1!$P60+[4]Лист1!$P60+[5]Лист1!$P60+[6]Лист1!$P60 -> 51.07
A61: 42737 | B61: 0.25 | C61: 12 | D61: =[1]Лист1!$D61+[2]Лист1!$D61+[3]Лист1!$D61+[4]Лист1!$D61+[5]Лист1!$D61+[6]Лист1!$D61 -> 46.64 | H61: 43102 | I61: 0.25 | J61: 12 | K61: =[1]Лист1!$J61+[2]Лист1!$J61+[3]Лист1!$J61+[4]Лист1!$J61+[5]Лист1!$J61+[6]Лист1!$J61 -> 46.69 | O61: 43467 | P61: 0.25 | Q61: 12 | R61: =[1]Лист1!$P61+[2]Лист1!$P61+[3]Лист1!$P61+[4]Лист1!$P61+[5]Лист1!$P61+[6]Лист1!$P61 -> 52.75
... A96: 42737 | B96: 0.97916667 | C96: 47 | D96: =[1]Лист1!$D96+[2]Лист1!$D96+[3]Лист1!$D96+[4]Лист1!$D96+[5]Лист1!$D96+[6]Лист1!$D96 -> 95.41 | H96: 43102 | I96: 0.97916667 | J96: 47 | K96: =[1]Лист1!$J96+[2]Лист1!$J96+[3]Лист1!$J96+[4]Лист1!$J96+[5]Лист1!$J96+[6]Лист1!$J96 -> 95.27 | O96: 43467 | P96: 0.97916667 | Q96: 47 | R96: =[1]Лист1!$P96+[2]Лист1!$P96+[3]Лист1!$P96+[4]Лист1!$P96+[5]Лист1!$P96+[6]Лист1!$P96 -> 91
A97: 42737 | B97: 24:00 | C97: 48 | D97: =[1]Лист1!$D97+[2]Лист1!$D97+[3]Лист1!$D97+[4]Лист1!$D97+[5]Лист1!$D97+[6]Лист1!$D97 -> 82.94 | H97: 43102 | I97: 24:00 | J97: 48 | K97: =[1]Лист1!$J97+[2]Лист1!$J97+[3]Лист1!$J97+[4]Лист1!$J97+[5]Лист1!$J97+[6]Лист1!$J97 -> 88.07 | O97: 43467 | P97: 24:00 | Q97: 48 | R97: =[1]Лист1!$P97+[2]Лист1!$P97+[3]Лист1!$P97+[4]Лист1!$P97+[5]Лист1!$P97+[6]Лист1!$P97 -> 84.5
A98: 42738 | B98: 0.020833333 | C98: 1 | D98: =[1]Лист1!$D98+[2]Лист1!$D98+[3]Лист1!$D98+[4]Лист1!$D98+[5]Лист1!$D98+[6]Лист1!$D98 -> 81.23 | H98: 43103 | I98: 0.020833333 | J98: 1 | K98: =[1]Лист1!$J98+[2]Лист1!$J98+[3]Лист1!$J98+[4]Лист1!$J98+[5]Лист1!$J98+[6]Лист1!$J98 -> 82.04 | O98: 43468 | P98: 0.020833333 | Q98: 1 | R98: =[1]Лист1!$P98+[2]Лист1!$P98+[3]Лист1!$P98+[4]Лист1!$P98+[5]Лист1!$P98+[6]Лист1!$P98 -> 78.13
A99: 42738 | B99: 0.041666667 | C99: 2 | D99: =[1]Лист1!$D99+[2]Лист1!$D99+[3]Лист1!$D99+[4]Лист1!$D99+[5]Лист1!$D99+[6]Лист1!$D99 -> 72.98 | H99: 43103 | I99: 0.041666667 | J99: 2 | K99: =[1]Лист1!$J99+[2]Лист1!$J99+[3]Лист1!$J99+[4]Лист1!$J99+[5]Лист1!$J99+[6]Лист1!$J99 -> 77.68 | O99: 43468 | P99: 0.041666667 | Q99: 2 | R99: =[1]Лист1!$P99+[2]Лист1!$P99+[3]Лист1!$P99+[4]Лист1!$P99+[5]Лист1!$P99+[6]Лист1!$P99 -> 72.84
A100: 42738 | B100: 0.0625 | C100: 3 | D100: =[1]Лист1!$D100+[2]Лист1!$D100+[3]Лист1!$D100+[4]Лист1!$D100+[5]Лист1!$D100+[6]Лист1!$D100 -> 67.47 | H100: 43103 | I100: 0.0625 | J100: 3 | K100: =[1]Лист1!$J100+[2]Лист1!$J100+[3]Лист1!$J100+[4]Лист1!$J100+[5]Лист1!$J100+[6]Лист1!$J100 -> 69.37 | O100: 43468 | P100: 0.0625 | Q100: 3 | R100: =[1]Лист1!$P100+[2]Лист1!$P100+[3]Лист1!$P100+[4]Лист1!$P100+[5]Лист1!$P100+[6]Лист1!$P100 -> 67.4
A101: 42738 | B101: 0.083333333 | C101: 4 | D101: =[1]Лист1!$D101+[2]Лист1!$D101+[3]Лист1!$D101+[4]Лист1!$D101+[5]Лист1!$D101+[6]Лист1!$D101 -> 59.1 | H101: 43103 | I101: 0.083333333 | J101: 4 | K101: =[1]Лист1!$J101+[2]Лист1!$J101+[3]Лист1!$J101+[4]Лист1!$J101+[5]Лист1!$J101+[6]Лист1!$J101 -> 64.84 | O101: 43468 | P101: 0.083333333 | Q101: 4 | R101: =[1]Лист1!$P101+[2]Лист1!$P101+[3]Лист1!$P101+[4]Лист1!$P101+[5]Лист1!$P101+[6]Лист1!$P101 -> 64.53
A102: 42738 | B102: 0.10416667 | C102: 5 | D102: =[1]Лист1!$D102+[2]Лист1!$D102+[3]Лист1!$D102+[4]Лист1!$D102+[5]Лист1!$D102+[6]Лист1!$D102 -> 55.32 | H102: 43103 | I102: 0.10416667 | J102: 5 | K102: =[1]Лист1!$J102+[2]Лист1!$J102+[3]Лист1!$J102+[4]Лист1!$J102+[5]Лист1!$J102+[6]Лист1!$J102 -> 57.27 | O102: 43468 | P102: 0.10416667 | Q102: 5 | R102: =[1]Лист1!$P102+[2]Лист1!$P102+[3]Лист1!$P102+[4]Лист1!$P102+[5]Лист1!$P102+[6]Лист1!$P102 -> 59.58
A103: 42738 | B103: 0.125 | C103: 6 | D103: =[1]Лист1!$D103+[2]Лист1!$D103+[3]Лист1!$D103+[4]Лист1!$D103+[5]Лист1!$D103+[6]Лист1!$D103 -> 51.66 | H103: 43103 | I103: 0.125 | J103: 6 | K103: =[1]Лист1!$J103+[2]Лист1!$J103+[3]Лист1!$J103+[4]Лист1!$J103+[5]Лист1!$J103+[6]Лист1!$J103 -> 54.31 | O103: 43468 | P103: 0.125 | Q103: 6 | R103: =[1]Лист1!$P103+[2]Лист1!$P103+[3]Лист1!$P103+[4]Лист1!$P103+[5]Лист1!$P103+[6]Лист1!$P103 -> 55.2
A104: 42738 | B104: 0.14583333 | C104: 7 | D104: =[1]Лист1!$D104+[2]Лист1!$D104+[3]Лист1!$D104+[4]Лист1!$D104+[5]Лист1!$D104+[6]Лист1!$D104 -> 52.56 | H104: 43103 | I104: 0.14583333 | J104: 7 | K104: =[1]Лист1!$J104+[2]Лист1!$J104+[3]Лист1!$J104+[4]Лист1!$J104+[5]Лист1!$J104+[6]Лист1!$J104 -> 48.29 | O104: 43468 | P104: 0.14583333 | Q104: 7 | R104: =[1]Лист1!$P104+[2]Лист1!$P104+[3]Лист1!$P104+[4]Лист1!$P104+[5]Лист1!$P104+[6]Лист1!$P104 -> 54.53
A105: 42738 | B105: 0.16666667 | C105: 8 | D105: =[1]Лист1!$D105+[2]Лист1!$D105+[3]Лист1!$D105+[4]Лист1!$D105+[5]Лист1!$D105+[6]Лист1!$D105 -> 47.95 | H105: 43103 | I105: 0.16666667 | J105: 8 | K105: =[1]Лист1!$J105+[2]Лист1!$J105+[3]Лист1!$J105+[4]Лист1!$J105+[5]Лист1!$J105+[6]Лист1!$J105 -> 48.55 | O105: 43468 | P105: 0.16666667 | Q105: 8 | R105: =[1]Лист1!$P105+[2]Лист1!$P105+[3]Лист1!$P105+[4]Лист1!$P105+[5]Лист1!$P105+[6]Лист1!$P105 -> 52.44
A106: 42738 | B106: 0.1875 | C106: 9 | D106: =[1]Лист1!$D106+[2]Лист1!$D106+[3]Лист1!$D106+[4]Лист1!$D106+[5]Лист1!$D106+[6]Лист1!$D106 -> 47.38 | H106: 43103 | I106: 0.1875 | J106: 9 | K106: =[1]Лист1!$J106+[2]Лист1!$J106+[3]Лист1!$J106+[4]Лист1!$J106+[5]Лист1!$J106+[6]Лист1!$J106 -> 47.16 | O106: 43468 | P106: 0.1875 | Q106: 9 | R106: =[1]Лист1!$P106+[2]Лист1!$P106+[3]Лист1!$P106+[4]Лист1!$P106+[5]Лист1!$P106+[6]Лист1!$P106 -> 52.51
A107: 42738 | B107: 0.20833333 | C107: 10 | D107: =[1]Лист1!$D107+[2]Лист1!$D107+[3]Лист1!$D107+[4]Лист1!$D107+[5]Лист1!$D107+[6]Лист1!$D107 -> 49.83 | H107: 43103 | I107: 0.20833333 | J107: 10 | K107: =[1]Лист1!$J107+[2]Лист1!$J107+[3]Лист1!$J107+[4]Лист1!$J107+[5]Лист1!$J107+[6]Лист1!$J107 -> 48.96 | O107: 43468 | P107: 0.20833333 | Q107: 10 | R107: =[1]Лист1!$P107+[2]Лист1!$P107+[3]Лист1!$P107+[4]Лист1!$P107+[5]Лист1!$P107+[6]Лист1!$P107 -> 52.5
A108: 42738 | B108: 0.22916667 | C108: 11 | D108: =[1]Лист1!$D108+[2]Лист1!$D108+[3]Лист1!$D108+[4]Лист1!$D108+[5]Лист1!$D108+[6]Лист1!$D108 -> 48.77 | H108: 43103 | I108: 0.22916667 | J108: 11 | K108: =[1]Лист1!$J108+[2]Лист1!$J108+[3]Лист1!$J108+[4]Лист1!$J108+[5]Лист1!$J108+[6]Лист1!$J108 -> 48.35 | O108: 43468 | P108: 0.22916667 | Q108: 11 | R108: =[1]Лист1!$P108+[2]Лист1!$P108+[3]Лист1!$P108+[4]Лист1!$P108+[5]Лист1!$P108+[6]Лист1!$P108 -> 53.98
...
